<?xml version="1.0" encoding="utf-8"?>
<!-- =================================================================================== -->
<!-- |    This document was autogenerated by xacro from robot_description.urdf.xacro   | -->
<!-- |    EDITING THIS FILE BY HAND IS NOT RECOMMENDED                                 | -->
<!-- =================================================================================== -->
<robot name="thymio" xmlns:xacro="https://www.ros.org/wiki/xacro">
  <material name="white">
    <color rgba="1.0 1.0 1.0 1.0"/>
  </material>
  <material name="black">
    <color rgba="0.175 0.175 0.175 1.0"/>
  </material>
  <gazebo reference="base_link">
    <material>Gazebo/White</material>
  </gazebo>
  <gazebo reference="left_wheel_link">
    <material>Gazebo/Black</material>
  </gazebo>
  <gazebo reference="right_wheel_link">
    <material>Gazebo/Black</material>
  </gazebo>
  <link name="base_link">
    <inertial>
      <mass value="0.216"/>
      <inertia ixx="0.000262242" ixy="0" ixz="0" iyy="0.00025425" iyz="0" izz="0.00025425"/>
    </inertial>
    <collision name="collision_body">
      <origin xyz="0 0 0.027"/>
      <geometry>
        <box size="0.11 0.112 0.045"/>
      </geometry>
      <material name="white"/>
    </collision>
    <collision name="collision_caster">
      <origin xyz="0.035 0 0.009"/>
      <geometry>
        <sphere radius="0.009"/>
      </geometry>
    </collision>
    <visual name="visual_body">
      <origin xyz="0 0 0.027"/>
      <geometry>
        <box size="0.11 0.112 0.045"/>
      </geometry>
      <material name="white"/>
    </visual>
    <visual name="visual_caster">
      <origin xyz="0.035 0 0.009"/>
      <geometry>
        <sphere radius="0.009"/>
      </geometry>
    </visual>
  </link>
  <joint name="left_wheel_joint" type="continuous">
    <parent link="base_link"/>
    <child link="left_wheel_link"/>
    <axis rpy="0 0 0" xyz="0 1 0"/>
    <origin xyz="-0.025 0.047 0.022"/>
    <joint_properties damping="0.0" friction="0.0"/>
  </joint>
  <link name="left_wheel_link">
    <inertial>
      <mass value="0.027"/>
      <inertia ixx="3.77325e-06" ixy="0" ixz="0" iyy="3.77325e-06" iyz="0" izz="6.534e-06"/>
    </inertial>
    <collision name="collision_left_wheel_link">
      <origin rpy="1.5707 0 0" xyz="0 0.00175 0.0"/>
      <geometry>
        <cylinder length="0.015" radius="0.022"/>
      </geometry>
    </collision>
    <visual name="visual_left_wheel_link">
      <origin rpy="1.5707 0 0" xyz="0 0.00175 0.0"/>
      <geometry>
        <cylinder length="0.015" radius="0.022"/>
      </geometry>
      <material name="black"/>
    </visual>
  </link>
  <joint name="right_wheel_joint" type="continuous">
    <parent link="base_link"/>
    <child link="right_wheel_link"/>
    <axis xyz="0 1 0"/>
    <origin rpy="0 0 0" xyz="-0.025 -0.047 0.022"/>
    <joint_properties damping="0.0" friction="0.0"/>
  </joint>
  <link name="right_wheel_link">
    <inertial>
      <mass value="0.027"/>
      <inertia ixx="3.77325e-06" ixy="0" ixz="0" iyy="3.77325e-06" iyz="0" izz="6.534e-06"/>
    </inertial>
    <collision name="collision_right_wheel_link">
      <origin rpy="1.5707 0 0" xyz="0 -0.00175 0.0"/>
      <geometry>
        <cylinder length="0.015" radius="0.022"/>
      </geometry>
    </collision>
    <visual name="visual_right_wheel_link">
      <origin rpy="1.5707 0 0" xyz="0 -0.00175 0.0"/>
      <geometry>
        <cylinder length="0.015" radius="0.022"/>
      </geometry>
      <material name="black"/>
    </visual>
  </link>
  <link name="sensor_laser">
    <inertial>
      <origin rpy="0 0 0" xyz="0 0 0"/>
      <mass value="0.01"/>
      <!-- RANDOM INERTIA BELOW -->
      <inertia ixx="0.000002" ixy="0" ixz="0" iyy="0.000002" iyz="0" izz="0.000002"/>
    </inertial>
    <visual>
      <origin rpy="0 0 0" xyz="0 0 0"/>
      <geometry>
        <cylinder length="0.006" radius="0.003"/>
      </geometry>
      <material name="white"/>
    </visual>
    <collision>
      <origin rpy="0 0 0" xyz="0 0 0"/>
      <geometry>
        <cylinder length="0.006" radius="0.003"/>
      </geometry>
    </collision>
  </link>
  <joint name="joint_sensor_laser" type="fixed">
    <origin rpy="0 0 0" xyz="0.055 0 0.022"/>
    <parent link="base_link"/>
    <child link="sensor_laser"/>
  </joint>
  <gazebo>
    <plugin filename="libgazebo_ros_diff_drive.so" name="differential_drive_controller">
      <alwaysOn>true</alwaysOn>
      <updateRate>20</updateRate>
      <leftJoint>right_wheel_joint</leftJoint>
      <rightJoint>left_wheel_joint</rightJoint>
      <wheelSeparation>0.0955</wheelSeparation>
      <wheelDiameter>0.044</wheelDiameter>
      <commandTopic>cmd_vel</commandTopic>
      <odometryTopic>odom</odometryTopic>
      <odometryFrame>odom</odometryFrame>
      <robotBaseFrame>base_link</robotBaseFrame>
    </plugin>
  </gazebo>
</robot>

