<?xml version="1.0"?>

<robot xmlns:xacro="https://www.ros.org/wiki/xacro" name="thymio">

    <xacro:include filename="$(find ros_basics_2019)/urdf/macros.xacro" />

    <xacro:arg name="left_wheel_mu" default="100.0"/>
    <xacro:property name="left_wheel_mu_p" value="$(arg left_wheel_mu)"/>

    <xacro:arg name="right_wheel_mu" default="100.0"/>
    <xacro:property name="right_wheel_mu_p" value="$(arg right_wheel_mu)"/>
    
    <xacro:property name="wheel_r" value="0.022"/>
    <xacro:property name="wheel_l" value="0.015"/>

    <xacro:arg name="mass" default="0.270"/>
    <xacro:property name="mass_p" value="$(arg mass)"/>

    <xacro:property name="body_mass" value="${mass_p * 0.80}"/>
    <xacro:property name="wheel_mass" value="${mass_p * 0.10}"/>



    <material name="white">
        <color rgba="1.0 1.0 1.0 1.0"/>
    </material>
    <material name="black">
        <color rgba="0.175 0.175 0.175 1.0"/>
    </material>
		<gazebo reference="base_link"> 
 <material>Gazebo/White</material> 
</gazebo>
<gazebo reference="left_wheel_link"> 
 <material>Gazebo/Black</material> 
</gazebo>
<gazebo reference="right_wheel_link"> 
 <material>Gazebo/Black</material> 
</gazebo>

    <link name="base_link">
        <inertial>
            <mass value="${body_mass}"/>
            <!-- <inertia ixx="${0.0012141 * body_mass}" ixy="0" ixz="0" iyy="${0.0011771 * body_mass}" iyz="0" izz="${0.00205365 * body_mass}"/> -->
            <xacro:box_inertia m="${body_mass}" x="0.11" y="0.112" z="0.045" />
        </inertial>
        
        <collision name="collision_body">
            <origin xyz="0 0 ${0.045 - 2*0.009}"/>
            <geometry>
                <box size="0.11 0.112 0.045"/>
            </geometry>
            <material name="white"/>
        </collision>
        <collision name="collision_caster">
            <origin xyz="0.035 0 0.009"/>
            <geometry>
                <sphere radius="0.009"/>
            </geometry>
        </collision>

        <visual name="visual_body">
            <origin xyz="0 0 ${0.045 - 2*0.009}"/>
            <geometry>
                <box size="0.11 0.112 0.045"/>
            </geometry>
            <material name="white"/>
        </visual>
        <visual name="visual_caster">
            <origin xyz="0.035 0 0.009"/>
            <geometry>
                <sphere radius="0.009"/>
            </geometry>
        </visual>
    </link>

    <joint name="left_wheel_joint" type="continuous">
        <parent link="base_link"/>
        <child link="left_wheel_link"/>
        <axis rpy="0 0 0" xyz="0 1 0"/>
        <origin xyz="-0.025 0.047 0.022"/>
        <joint_properties damping="0.0" friction="0.0" />
    </joint>

    <link name="left_wheel_link">
        <inertial>
            <mass value="${wheel_mass}"/>
            <!-- <inertia ixx="${0.0001452 * wheel_mass}" ixy="0" ixz="0" iyy="${0.000242 * wheel_mass}" iyz="0" izz="${0.0001452 * wheel_mass}"/> -->
            <xacro:cylinder_inertia m="${wheel_mass}" r="${wheel_r}" h="${wheel_l}" />
        </inertial>

        <collision name="collision_left_wheel_link">
            <origin xyz="0 0.00175 0.0" rpy="1.5707 0 0"/>
            <geometry>
                <cylinder radius="${wheel_r}" length="${wheel_l}"/>
            </geometry>
        </collision>
        
        <visual name="visual_left_wheel_link">
            <origin xyz="0 0.00175 0.0" rpy="1.5707 0 0"/>
            <geometry>
                <cylinder length="${wheel_l}" radius="${wheel_r}"/>
            </geometry>
            <material name="black"/>
        </visual>
    </link>

    <joint name="right_wheel_joint" type="continuous">
        <parent link="base_link"/>
        <child link="right_wheel_link"/>
        <axis xyz="0 1 0"/>
        <origin rpy="0 0 0" xyz="-0.025 -0.047 0.022"/>
        <joint_properties damping="0.0" friction="0.0" />
    </joint>

    <link name="right_wheel_link">
        <inertial>
            <mass value="${wheel_mass}"/>
            <!-- <inertia ixx="${0.0001452 * wheel_mass}" ixy="0" ixz="0" iyy="${0.000242 * wheel_mass}" iyz="0" izz="${0.0001452 * wheel_mass}"/> -->
            <xacro:cylinder_inertia m="${wheel_mass}" r="${wheel_r}" h="${wheel_l}" />
        </inertial>
        
        <collision name="collision_right_wheel_link">
            <origin xyz="0 -0.00175 0.0" rpy="1.5707 0 0"/>
            <geometry>
                <cylinder length="${wheel_l}" radius="${wheel_r}"/>
            </geometry>
        </collision>
        
        <visual name="visual_right_wheel_link">
            <origin xyz="0 -0.00175 0.0" rpy="1.5707 0 0"/>
            <geometry>
                <cylinder length="${wheel_l}" radius="${wheel_r}"/>
            </geometry>
            <material name="black"/>
        </visual>
    </link>

    <link name="sensor_laser">
    <inertial>
      <origin xyz="0 0 0" rpy="0 0 0" />
      <mass value="0.01" />
      
      <inertia ixx="0.000002" ixy="0" ixz="0" iyy="0.000002" iyz="0" izz="0.000002"/>
    </inertial>
 
    <visual>
      <origin xyz="0 0 0" rpy="0 0 0" />
      <geometry>
        <cylinder radius="0.003" length="0.006"/>
      </geometry>
      <material name="white" />
    </visual>
 
    <collision>
      <origin xyz="0 0 0" rpy="0 0 0"/>
      <geometry>
        <cylinder radius="0.003" length="0.003"/>
      </geometry>
    </collision>
  </link>
 
  <joint name="joint_sensor_laser" type="fixed">
    <origin xyz="0.056 0 0.022" rpy="0 0 0"/>
    <parent link="base_link"/>
    <child link="sensor_laser"/>
  </joint>

    <gazebo>
        <plugin name="differential_drive_controller" filename="libgazebo_ros_diff_drive.so">
            <alwaysOn>true</alwaysOn>
            <updateRate>20</updateRate>
            <leftJoint>right_wheel_joint</leftJoint>
            <rightJoint>left_wheel_joint</rightJoint>
            <wheelSeparation>0.0955</wheelSeparation>
            <wheelDiameter>0.044</wheelDiameter>

            <commandTopic>cmd_vel</commandTopic>
            <odometryTopic>odom</odometryTopic>
            <odometryFrame>odom</odometryFrame>

            <robotBaseFrame>base_link</robotBaseFrame>
        </plugin>
    </gazebo>
<gazebo reference ="sensor_laser">
    <sensor type="ray" name="head_hokuyo_sensor">
      <pose>0 0 0 0 0 0</pose>
      <visualize>true</visualize>
      <update_rate>10</update_rate>
      <ray>
        <scan>
          <horizontal>
            <samples>720</samples>
            <resolution>1</resolution>
            <min_angle>-1</min_angle>
            <max_angle>1</max_angle>
          </horizontal>
        </scan>
        <range>
          <min>0.01</min>
          <max>0.14</max>
          <resolution>0.01</resolution>
        </range>
        <noise>
          <type>gaussian</type>
          <mean>0.0</mean>
          <stddev>0.01</stddev>
        </noise>
      </ray>
      <plugin name="laser" filename="libgazebo_ros_laser.so">
        <topicName>/thymio/scan</topicName>
        <frameName>sensor_laser</frameName>
      </plugin>
    </sensor>
  </gazebo>


</robot>
