<?xml version="1.0"?>

<robot xmlns:xacro="https://www.ros.org/wiki/xacro" name="Michedi">

    <xacro:include filename="$(find ros_basics_2019)/urdf/macros.xacro" />
    <xacro:include filename="$(find ros_basics_2019)/urdf/materials.xacro" />


<gazebo reference="link_base"> 
 <material>Gazebo/White</material> 
</gazebo>
<gazebo reference="link_wheel_right"> 
 <material>Gazebo/Black</material> 
</gazebo>
<gazebo reference="link_wheel_left"> 
 <material>Gazebo/Black</material> 
</gazebo>

    <!-- Design your robot here -->

<link name="link_base">
    <inertial>
        <mass value="0.216"/>
        <origin rpy="0 0 0" xyz="0 0 0.022"/>
        <xacro:box_inertia m="0.216" x="0.117" y="0.112" z="0.053"/>
    </inertial>

<collision name="collision_base">
<geometry>
	<box size="0.117 0.112 0.053"/>
</geometry>
</collision>

<visual name="visual_base">
<origin rpy="0 0 0" xyz="0 0 0.022"/>
<geometry>
        <box size="0.117 0.112 0.053"/>
</geometry>
<material name="white"/>
</visual>

<collision name="collision_cone">
<origin xyz="0.055 0 -0.011"/>
<geometry>
	<sphere radius="0.011"/>
</geometry>
</collision>

<visual name="visual_cone">
<origin xyz="0.04 0 -0.011"/>
<geometry>
        <sphere radius="0.011"/>
</geometry>
</visual>
</link>


<link name="link_wheel_right">
    <inertial>
        <mass value="0.027"/>
        <origin rpy="1.5707 0 0" xyz="0 0 0"/>
      	<xacro:cylinder_inertia m="0.027" r="0.022" h="0.015" />
</inertial>
    <collision name="link_wheel_right_collision">
        <origin rpy="1.5707 0 0" xyz="0 0 0" />
        <geometry>
            <cylinder length="0.015" radius="0.022"/>
        </geometry>
    </collision>
    
    <visual name="link_wheel_right_visual">
        <origin rpy="1.5707 0 0" xyz="0 0 0"/>
        <geometry>
            <cylinder length="0.015" radius="0.022"/>
        </geometry>
    </visual>
</link>

<link name="link_wheel_left">
    <inertial>
        <mass value="0.027"/>
        <origin rpy="1.5707 0 0" xyz="0 0 0"/>
        <xacro:cylinder_inertia m="0.027" r="0.022" h="0.015" />
    </inertial>
    <collision name="link_wheel_left_collision">
        <origin rpy="1.5707 0 0" xyz="0 0 0" />
        <geometry>
            <cylinder length="0.015" radius="0.022"/>
        </geometry>
    </collision>
    
    <visual name="link_wheel_left_visual">
        <origin rpy="1.5707 0 0" xyz="0 0 0"/>
        <geometry>
            <cylinder length="0.015" radius="0.022"/>
        </geometry>
    </visual>
</link>

<joint name="joint_left_wheel" type="continuous">
    <origin rpy="0 0 0" xyz="-0.02 0.05 0"/>
    <child link="link_wheel_left" />
    <parent link="link_base"/>
    <axis rpy="0 0 0" xyz="0 1 0"/>  
     <dynamics damping="0.0" friction="0.0" />
   
</joint>

<joint name="joint_right_wheel" type="continuous">
    <origin rpy="0 0 0" xyz="-0.02 -0.05 0"/>
    <child link="link_wheel_right" />
    <parent link="link_base"/>
    <axis rpy="0 0 0" xyz="0 1 0"/>
    <dynamics damping="0.0" friction="0.0" />
   
</joint>



    <!-- Below you will find samples of gazebo plugins you may want to use. -->
    <!-- These should be adapted to your robot's design -->
    <gazebo reference="YOUR_SENSOR_LINK">  
        <sensor type="ray" name="laser_right">
            <pose>0 0 0 0 0 0</pose>
            <ray>
                <scan>
                    <horizontal>
                        <samples>13</samples>
                        <resolution>1</resolution>
                        <min_angle>-1.571</min_angle>
                        <max_angle>1.571</max_angle>
                    </horizontal>
                </scan>
                <range>
                    <!-- You can edit adapt these to your robot's size -->
                    <min>0.0005</min>
                    <max>0.04</max>
                    <resolution>0.0001</resolution>
                </range>
            </ray>
            <plugin name="laser" filename="libgazebo_ros_laser.so" >
                <topicName>YOUR_ROBOT_LASER/scan</topicName>
                <frameName>YOUR_ROBOT_LASER_LINK</frameName>
            </plugin>
            <always_on>1</always_on>
            <update_rate>10</update_rate>
            <visualize>true</visualize>
        </sensor>
    </gazebo> 

    <gazebo>
        <plugin name="differential_drive_controller" filename="libgazebo_ros_diff_drive.so">
            <alwaysOn>true</alwaysOn>
            <updateRate>20</updateRate>
            <leftJoint>joint_left_wheel</leftJoint>
            <rightJoint>joint_right_wheel</rightJoint>
            <wheelSeparation>=0.08</wheelSeparation>
            <wheelDiameter>0.044</wheelDiameter>
            

            <commandTopic>cmd_vel</commandTopic>
            <odometryTopic>odom</odometryTopic>
            <odometryFrame>odom</odometryFrame>

            <robotBaseFrame>link_base</robotBaseFrame>
        </plugin>
    </gazebo>

</robot>
